I'm sorry, but an uncaught exception occurred.

While running game code:
  File "game/script.rpy", line 168, in script
    scene lean_on_hand with Pixellate(1.0)
TypeError: __init__() takes at least 3 arguments (4 given)

-- Full Traceback ------------------------------------------------------------

Full traceback:
  File "game/script.rpy", line 168, in script
    scene lean_on_hand with Pixellate(1.0)
  File "C:\Users\gina\Documents\Ren'py\renpy-7.4.2-sdk/renpy/ast.py", line 1397, in execute
    renpy.exports.with_statement(trans, paired)
  File "C:\Users\gina\Documents\Ren'py\renpy-7.4.2-sdk/renpy/exports.py", line 1646, in with_statement
    return renpy.game.interface.do_with(trans, paired, clear=clear)
  File "C:\Users\gina\Documents\Ren'py\renpy-7.4.2-sdk/renpy/display/core.py", line 2610, in do_with
    clear=clear)
  File "C:\Users\gina\Documents\Ren'py\renpy-7.4.2-sdk/renpy/display/core.py", line 3101, in interact
    repeat, rv = self.interact_core(preloads=preloads, trans_pause=trans_pause, pause=pause, pause_start=pause_start, **kwargs)
  File "C:\Users\gina\Documents\Ren'py\renpy-7.4.2-sdk/renpy/display/core.py", line 3460, in interact_core
    new_widget=layers_root)
  File "C:\Users\gina\Documents\Ren'py\renpy-7.4.2-sdk/renpy/curry.py", line 48, in __call__
    return self.callable(*(self.args + args), **merged_kwargs)
TypeError: __init__() takes at least 3 arguments (4 given)

Windows-10-10.0.19041
Ren'Py 7.4.3.1414
419 Project renpy 1.0
Mon Mar 15 20:23:40 2021
